Workbook

Sheet Sheet1
A1: 订货号 | B1: 系列 | C1: 尺寸
A2: 6SL3310-1TE32-1AA3 | B2: =IFERROR(_xlfn.XLOOKUP(A2,全部产品!B:B,全部产品!F:F), IFERROR(_xlfn.XLOOKUP(A2,全部产品!C:C,全部产品!F:F), IFERROR(_xlfn.XLOOKUP(A2,全部产品!D:D,全部产品!F:F), _xlfn.XLOOKUP(A2,全部产品!E:E,全部产品!F:F)))) -> S120 AC/AC | C2: =IFERROR(_xlfn.XLOOKUP(A2,全部产品!B:B,全部产品!A:A), IFERROR(_xlfn.XLOOKUP(A2,全部产品!C:C,全部产品!A:A), IFERROR(_xlfn.XLOOKUP(A2,全部产品!D:D,全部产品!A:A), _xlfn.XLOOKUP(A2,全部产品!E:E,全部产品!A:A)))) -> FX
A3: 6SL3310-1TE32-6AA3 | B3: =IFERROR(_xlfn.XLOOKUP(A3,全部产品!B:B,全部产品!F:F), IFERROR(_xlfn.XLOOKUP(A3,全部产品!C:C,全部产品!F:F), IFERROR(_xlfn.XLOOKUP(A3,全部产品!D:D,全部产品!F:F), _xlfn.XLOOKUP(A3,全部产品!E:E,全部产品!F:F)))) -> S120 AC/AC | C3: =IFERROR(_xlfn.XLOOKUP(A3,全部产品!B:B,全部产品!A:A), IFERROR(_xlfn.XLOOKUP(A3,全部产品!C:C,全部产品!A:A), IFERROR(_xlfn.XLOOKUP(A3,全部产品!D:D,全部产品!A:A), _xlfn.XLOOKUP(A3,全部产品!E:E,全部产品!A:A)))) -> FX
A4: 6SL3310-1TE33-1AA3 | B4: =IFERROR(_xlfn.XLOOKUP(A4,全部产品!B:B,全部产品!F:F), IFERROR(_xlfn.XLOOKUP(A4,全部产品!C:C,全部产品!F:F), IFERROR(_xlfn.XLOOKUP(A4,全部产品!D:D,全部产品!F:F), _xlfn.XLOOKUP(A4,全部产品!E:E,全部产品!F:F)))) -> S120 AC/AC | C4: =IFERROR(_xlfn.XLOOKUP(A4,全部产品!B:B,全部产品!A:A), IFERROR(_xlfn.XLOOKUP(A4,全部产品!C:C,全部产品!A:A), IFERROR(_xlfn.XLOOKUP(A4,全部产品!D:D,全部产品!A:A), _xlfn.XLOOKUP(A4,全部产品!E:E,全部产品!A:A)))) -> GX
A5: 6SL3310-1TE33-8AA3 | B5: =IFERROR(_xlfn.XLOOKUP(A5,全部产品!B:B,全部产品!F:F), IFERROR(_xlfn.XLOOKUP(A5,全部产品!C:C,全部产品!F:F), IFERROR(_xlfn.XLOOKUP(A5,全部产品!D:D,全部产品!F:F), _xlfn.XLOOKUP(A5,全部产品!E:E,全部产品!F:F)))) -> S120 AC/AC | C5: =IFERROR(_xlfn.XLOOKUP(A5,全部产品!B:B,全部产品!A:A), IFERROR(_xlfn.XLOOKUP(A5,全部产品!C:C,全部产品!A:A), IFERROR(_xlfn.XLOOKUP(A5,全部产品!D:D,全部产品!A:A), _xlfn.XLOOKUP(A5,全部产品!E:E,全部产品!A:A)))) -> GX
A6: 6SL3310-1TE35-0AA3 | B6: =IFERROR(_xlfn.XLOOKUP(A6,全部产品!B:B,全部产品!F:F), IFERROR(_xlfn.XLOOKUP(A6,全部产品!C:C,全部产品!F:F), IFERROR(_xlfn.XLOOKUP(A6,全部产品!D:D,全部产品!F:F), _xlfn.XLOOKUP(A6,全部产品!E:E,全部产品!F:F)))) -> S120 AC/AC | C6: =IFERROR(_xlfn.XLOOKUP(A6,全部产品!B:B,全部产品!A:A), IFERROR(_xlfn.XLOOKUP(A6,全部产品!C:C,全部产品!A:A), IFERROR(_xlfn.XLOOKUP(A6,全部产品!D:D,全部产品!A:A), _xlfn.XLOOKUP(A6,全部产品!E:E,全部产品!A:A)))) -> GX
A7: 6SL3310-1TE32-1AA0 | B7: =IFERROR(_xlfn.XLOOKUP(A7,全部产品!B:B,全部产品!F:F), IFERROR(_xlfn.XLOOKUP(A7,全部产品!C:C,全部产品!F:F), IFERROR(_xlfn.XLOOKUP(A7,全部产品!D:D,全部产品!F:F), _xlfn.XLOOKUP(A7,全部产品!E:E,全部产品!F:F)))) -> S120 AC/AC | C7: =IFERROR(_xlfn.XLOOKUP(A7,全部产品!B:B,全部产品!A:A), IFERROR(_xlfn.XLOOKUP(A7,全部产品!C:C,全部产品!A:A), IFERROR(_xlfn.XLOOKUP(A7,全部产品!D:D,全部产品!A:A), _xlfn.XLOOKUP(A7,全部产品!E:E,全部产品!A:A)))) -> FX
A8: 6SL3310-1TE32-6AA0 | B8: =IFERROR(_xlfn.XLOOKUP(A8,全部产品!B:B,全部产品!F:F), IFERROR(_xlfn.XLOOKUP(A8,全部产品!C:C,全部产品!F:F), IFERROR(_xlfn.XLOOKUP(A8,全部产品!D:D,全部产品!F:F), _xlfn.XLOOKUP(A8,全部产品!E:E,全部产品!F:F)))) -> S120 AC/AC | C8: =IFERROR(_xlfn.XLOOKUP(A8,全部产品!B:B,全部产品!A:A), IFERROR(_xlfn.XLOOKUP(A8,全部产品!C:C,全部产品!A:A), IFERROR(_xlfn.XLOOKUP(A8,全部产品!D:D,全部产品!A:A), _xlfn.XLOOKUP(A8,全部产品!E:E,全部产品!A:A)))) -> FX
A9: 6SL3310-1TE33-1AA0 | B9: =IFERROR(_xlfn.XLOOKUP(A9,全部产品!B:B,全部产品!F:F), IFERROR(_xlfn.XLOOKUP(A9,全部产品!C:C,全部产品!F:F), IFERROR(_xlfn.XLOOKUP(A9,全部产品!D:D,全部产品!F:F), _xlfn.XLOOKUP(A9,全部产品!E:E,全部产品!F:F)))) -> S120 AC/AC | C9: =IFERROR(_xlfn.XLOOKUP(A9,全部产品!B:B,全部产品!A:A), IFERROR(_xlfn.XLOOKUP(A9,全部产品!C:C,全部产品!A:A), IFERROR(_xlfn.XLOOKUP(A9,全部产品!D:D,全部产品!A:A), _xlfn.XLOOKUP(A9,全部产品!E:E,全部产品!A:A)))) -> GX
A10: 6SL3310-1TE33-8AA0 | B10: =IFERROR(_xlfn.XLOOKUP(A10,全部产品!B:B,全部产品!F:F), IFERROR(_xlfn.XLOOKUP(A10,全部产品!C:C,全部产品!F:F), IFERROR(_xlfn.XLOOKUP(A10,全部产品!D:D,全部产品!F:F), _xlfn.XLOOKUP(A10,全部产品!E:E,全部产品!F:F)))) -> S120 AC/AC | C10: =IFERROR(_xlfn.XLOOKUP(A10,全部产品!B:B,全部产品!A:A), IFERROR(_xlfn.XLOOKUP(A10,全部产品!C:C,全部产品!A:A), IFERROR(_xlfn.XLOOKUP(A10,全部产品!D:D,全部产品!A:A), _xlfn.XLOOKUP(A10,全部产品!E:E,全部产品!A:A)))) -> GX
A11: 6SL3310-1TE35-0AA0 | B11: =IFERROR(_xlfn.XLOOKUP(A11,全部产品!B:B,全部产品!F:F), IFERROR(_xlfn.XLOOKUP(A11,全部产品!C:C,全部产品!F:F), IFERROR(_xlfn.XLOOKUP(A11,全部产品!D:D,全部产品!F:F), _xlfn.XLOOKUP(A11,全部产品!E:E,全部产品!F:F)))) -> S120 AC/AC | C11: =IFERROR(_xlfn.XLOOKUP(A11,全部产品!B:B,全部产品!A:A), IFERROR(_xlfn.XLOOKUP(A11,全部产品!C:C,全部产品!A:A), IFERROR(_xlfn.XLOOKUP(A11,全部产品!D:D,全部产品!A:A), _xlfn.XLOOKUP(A11,全部产品!E:E,全部产品!A:A)))) -> GX
A12: 6SL3320-1TE32-1AA3 | B12: =IFERROR(_xlfn.XLOOKUP(A12,全部产品!B:B,全部产品!F:F), IFERROR(_xlfn.XLOOKUP(A12,全部产品!C:C,全部产品!F:F), IFERROR(_xlfn.XLOOKUP(A12,全部产品!D:D,全部产品!F:F), _xlfn.XLOOKUP(A12,全部产品!E:E,全部产品!F:F)))) -> S120 MM | C12: =IFERROR(_xlfn.XLOOKUP(A12,全部产品!B:B,全部产品!A:A), IFERROR(_xlfn.XLOOKUP(A12,全部产品!C:C,全部产品!A:A), IFERROR(_xlfn.XLOOKUP(A12,全部产品!D:D,全部产品!A:A), _xlfn.XLOOKUP(A12,全部产品!E:E,全部产品!A:A)))) -> FX
A13: 6SL3320-1TE32-6AA3 | B13: =IFERROR(_xlfn.XLOOKUP(A13,全部产品!B:B,全部产品!F:F), IFERROR(_xlfn.XLOOKUP(A13,全部产品!C:C,全部产品!F:F), IFERROR(_xlfn.XLOOKUP(A13,全部产品!D:D,全部产品!F:F), _xlfn.XLOOKUP(A13,全部产品!E:E,全部产品!F:F)))) -> S120 MM | C13: =IFERROR(_xlfn.XLOOKUP(A13,全部产品!B:B,全部产品!A:A), IFERROR(_xlfn.XLOOKUP(A13,全部产品!C:C,全部产品!A:A), IFERROR(_xlfn.XLOOKUP(A13,全部产品!D:D,全部产品!A:A), _xlfn.XLOOKUP(A13,全部产品!E:E,全部产品!A:A)))) -> FX
... A445: 6SL3710-2GH41-5AA0 | B445: =IFERROR(_xlfn.XLOOKUP(A445,全部产品!B:B,全部产品!F:F), IFERROR(_xlfn.XLOOKUP(A445,全部产品!C:C,全部产品!F:F), IFERROR(_xlfn.XLOOKUP(A445,全部产品!D:D,全部产品!F:F), _xlfn.XLOOKUP(A445,全部产品!E:E,全部产品!F:F)))) -> G150 | C445: =IFERROR(_xlfn.XLOOKUP(A445,全部产品!B:B,全部产品!A:A), IFERROR(_xlfn.XLOOKUP(A445,全部产品!C:C,全部产品!A:A), IFERROR(_xlfn.XLOOKUP(A445,全部产品!D:D,全部产品!A:A), _xlfn.XLOOKUP(A445,全部产品!E:E,全部产品!A:A)))) -> JX

Sheet 全部产品
A1: 尺寸 | B1: 订货号 | C1: 订货号 | D1: 订货号 | E1: 订货号 | F1: 描述 | G1: 电压等级 | H1: 功率KW | I1: PWB数量 | J1: PWB1规格 | K1: PWB2规格 | L1: PWB3规格 | M1: PWB4规格 | N1: PWB5规格 | O1: PWB6规格 | P1: PWB7规格 | Q1: PWB8规格
A3: S120 AC/AC chassis
A4: FX | B4: 6SL3310-1TE32-1AA3 | D4: 6SL3310-1TE32-1AA0 | F4: S120 AC/AC | G4: 380-480 3AC | H4: 110 | I4: 1 | J4: 整流+U/V/W
A5: FX | B5: 6SL3310-1TE32-6AA3 | D5: 6SL3310-1TE32-6AA0 | F5: S120 AC/AC | G5: 380-480 3AC | H5: 132 | I5: 1 | J5: 整流+U/V/W
A6: GX | B6: 6SL3310-1TE33-1AA3 | D6: 6SL3310-1TE33-1AA0 | F6: S120 AC/AC | G6: 380-480 3AC | H6: 160 | I6: 1 | J6: 整流+U/V/W
A7: GX | B7: 6SL3310-1TE33-8AA3 | D7: 6SL3310-1TE33-8AA0 | F7: S120 AC/AC | G7: 380-480 3AC | H7: 200 | I7: 1 | J7: 整流+U/V/W
A8: GX | B8: 6SL3310-1TE35-0AA3 | D8: 6SL3310-1TE35-0AA0 | F8: S120 AC/AC | G8: 380-480 3AC | H8: 250 | I8: 1 | J8: 整流+U/V/W
A9: S120 MM chassis
A10: FX | B10: 6SL3320-1TE32-1AA3 | C10: 6SL3320-1TE32-1AC3 | D10: 6SL3320-1TE32-1AA0 | E10: 6SL3320-1TE32-1AC0 | F10: S120 MM | G10: 510-720 DC | H10: 110 | I10: 1 | J10: U/V/W
A11: FX | B11: 6SL3320-1TE32-6AA3 | C11: 6SL3320-1TE32-6AC3 | D11: 6SL3320-1TE32-6AA0 | E11: 6SL3320-1TE32-6AC0 | F11: S120 MM | G11: 510-720 DC | H11: 132 | I11: 1 | J11: U/V/W
A12: GX | B12: 6SL3320-1TE33-1AA3 | C12: 6SL3320-1TE33-1AC3 | D12: 6SL3320-1TE33-1AA0 | E12: 6SL3320-1TE33-1AC0 | F12: S120 MM | G12: 510-720 DC | H12: 160 | I12: 1 | J12: U/V/W
A13: GX | B13: 6SL3320-1TE33-8AA3 | C13: 6SL3320-1TE33-8AC3 | D13: 6SL3320-1TE33-8AA0 | E13: 6SL3320-1TE33-8AC0 | F13: S120 MM | G13: 510-720 DC | H13: 200 | I13: 1 | J13: U/V/W
A14: GX | B14: 6SL3320-1TE35-0AA3 | C14: 6SL3320-1TE35-0AC3 | D14: 6SL3320-1TE35-0AA0 | E14: 6SL3320-1TE35-0AC0 | F14: S120 MM | G14: 510-720 DC | H14: 250 | I14: 1 | J14: U/V/W
A15: HX | B15: 6SL3320-1TE36-1AA3 | D15: 6SL3320-1TE36-1AA0 | F15: S120 MM | G15: 510-720 DC | H15: 315 | I15: 2 | J15: U | K15: V/W
A16: HX | B16: 6SL3320-1TE37-5AA3 | D16: 6SL3320-1TE37-5AA0 | F16: S120 MM | G16: 510-720 DC | H16: 400 | I16: 2 | J16: U | K16: V/W
A17: HX | B17: 6SL3320-1TE38-4AA3 | D17: 6SL3320-1TE38-4AA0 | F17: S120 MM | G17: 510-720 DC | H17: 450 | I17: 2 | J17: U | K17: V/W
A18: JX | B18: 6SL3320-1TE41-0AA3 | D18: 6SL3320-1TE41-0AA0 | F18: S120 MM | G18: 510-720 DC | H18: 560 | I18: 3 | J18: U | K18: V | L18: W
A19: JX | B19: 6SL3320-1TE41-2AA3 | D19: 6SL3320-1TE41-2AA0 | F19: S120 MM | G19: 510-720 DC | H19: 710 | I19: 3 | J19: U | K19: V | L19: W
A20: JX | B20: 6SL3320-1TE41-4AA3 | D20: 6SL3320-1TE41-4AA0 | F20: S120 MM | G20: 510-720 DC | H20: 800 | I20: 3 | J20: U | K20: V | L20: W
A21: FX | B21: 6SL3320-1TG28-5AA3 | C21: 6SL3320-1TG28-5AC3 | D21: 6SL3320-1TG28-5AA0 | E21: 6SL3320-1TG28-5AC0 | F21: S120 MM | G21: 675-1035 DC | H21: 75 | I21: 1 | J21: U/V/W
A22: FX | B22: 6SL3320-1TG31-0AA3 | C22: 6SL3320-1TG31-0AC3 | D22: 6SL3320-1TG31-0AA0 | E22: 6SL3320-1TG31-0AC0 | F22: S120 MM | G22: 675-1035 DC | H22: 90 | I22: 1 | J22: U/V/W
A23: FX | B23: 6SL3320-1TG31-2AA3 | C23: 6SL3320-1TG31-2AC3 | D23: 6SL3320-1TG31-2AA0 | E23: 6SL3320-1TG31-2AC0 | F23: S120 MM | G23: 675-1035 DC | H23: 110 | I23: 1 | J23: U/V/W
A24: FX | B24: 6SL3320-1TG31-5AA3 | C24: 6SL3320-1TG31-5AC3 | D24: 6SL3320-1TG31-5AA0 | E24: 6SL3320-1TG31-5AC0 | F24: S120 MM | G24: 675-1035 DC | H24: 132 | I24: 1 | J24: U/V/W
A25: GX | B25: 6SL3320-1TG31-8AA3 | C25: 6SL3320-1TG31-8AC3 | D25: 6SL3320-1TG31-8AA0 | E25: 6SL3320-1TG31-8AC0 | F25: S120 MM | G25: 675-1035 DC | H25: 160 | I25: 1 | J25: U/V/W
A26: GX | B26: 6SL3320-1TG32-2AA3 | C26: 6SL3320-1TG32-2AC3 | D26: 6SL3320-1TG32-2AA0 | E26: 6SL3320-1TG32-2AC0 | F26: S120 MM | G26: 675-1035 DC | H26: 200 | I26: 1 | J26: U/V/W
A27: GX | B27: 6SL3320-1TG32-6AA3 | C27: 6SL3320-1TG32-6AC3 | D27: 6SL3320-1TG32-6AA0 | E27: 6SL3320-1TG32-6AC0 | F27: S120 MM | G27: 675-1035 DC | H27: 250 | I27: 1 | J27: U/V/W
A28: GX | B28: 6SL3320-1TG33-3AA3 | C28: 6SL3320-1TG33-3AC3 | D28: 6SL3320-1TG33-3AA0 | E28: 6SL3320-1TG33-3AC0 | F28: S120 MM | G28: 675-1035 DC | H28: 315 | I28: 1 | J28: U/V/W
A29: HX | B29: 6SL3320-1TG34-1AA3 | D29: 6SL3320-1TG34-1AA0 | F29: S120 MM | G29: 675-1035 DC | H29: 400 | I29: 2 | J29: U | K29: V/W
A30: HX | B30: 6SL3320-1TG34-7AA3 | D30: 6SL3320-1TG34-7AA0 | F30: S120 MM | G30: 675-1035 DC | H30: 450 | I30: 2 | J30: U | K30: V/W
A31: HX | B31: 6SL3320-1TG35-8AA3 | D31: 6SL3320-1TG35-8AA0 | F31: S120 MM | G31: 675-1035 DC | H31: 560 | I31: 2 | J31: U | K31: V/W
A32: JX | B32: 6SL3320-1TG37-4AA3 | D32: 6SL3320-1TG37-4AA0 | F32: S120 MM | G32: 675-1035 DC | H32: 710 | I32: 3 | J32: U | K32: V | L32: W
A33: JX | B33: 6SL3320-1TG38-1AA3 | D33: 6SL3320-1TG38-1AA0 | F33: S120 MM | G33: 675-1035 DC | H33: 800 | I33: 3 | J33: U | K33: V | L33: W
A34: JX | B34: 6SL3320-1TG38-8AA3 | D34: 6SL3320-1TG38-8AA0 | F34: S120 MM | G34: 675-1035 DC | H34: 900 | I34: 3 | J34: U | K34: V | L34: W
A35: JX | B35: 6SL3320-1TG41-0AA3 | D35: 6SL3320-1TG41-0AA0 | F35: S120 MM | G35: 675-1035 DC | H35: 1000 | I35: 3 | J35: U | K35: V | L35: W
A36: JX | B36: 6SL3320-1TG41-3AA3 | D36: 6SL3320-1TG41-3AA0 | F36: S120 MM | G36: 675-1035 DC | H36: 1200 | I36: 3 | J36: U | K36: V | L36: W
A37: S120 ALM chassis
A38: FX | B38: 6SL3330-7TE32-1AA3 | C38: 6SL3330-7TE32-1AB3 | D38: 6SL3330-7TE32-1AA0 | E38: 6SL3330-7TE32-1AB0 | F38: S120 ALM | G38: 380-480 3AC | H38: 132 | I38: 1 | J38: U/V/W
A39: FX | B39: 6SL3330-7TE32-6AA3 | C39: 6SL3330-7TE32-6AB3 | D39: 6SL3330-7TE32-6AA0 | E39: 6SL3330-7TE32-6AB0 | F39: S120 ALM | G39: 380-480 3AC | H39: 160 | I39: 1 | J39: U/V/W
A40: GX | B40: 6SL3330-7TE33-8AA3 | C40: 6SL3330-7TE33-8AB3 | D40: 6SL3330-7TE33-8AA0 | E40: 6SL3330-7TE33-8AB0 | F40: S120 ALM | G40: 380-480 3AC | H40: 235 | I40: 1 | J40: U/V/W
A41: GX | B41: 6SL3330-7TE35-0AA3 | C41: 6SL3330-7TE35-0AB3 | D41: 6SL3330-7TE35-0AA0 | E41: 6SL3330-7TE35-0AB0 | F41: S120 ALM | G41: 380-480 3AC | H41: 300 | I41: 1 | J41: U/V/W
...
